[2023-08-03 15:00:54] INFO : Data read successfully from the local CSV file. (extract.py:50)
[2023-08-03 15:00:54] INFO : Done reading CSV data from local (test_run_elt.py:38)
[2023-08-03 15:00:54] INFO : Starting transform with localsource data... (test_run_elt.py:56)
[2023-08-03 15:00:54] INFO : Done transforming localsource data. (test_run_elt.py:58)
[2023-08-03 15:00:54] INFO : => STARTING VALIDATE... (test_run_elt.py:68)
[2023-08-03 15:00:54] INFO : Starting data validation with localsource data... (test_run_elt.py:70)
[2023-08-03 15:00:54] WARNING : Data test cases_vs_deaths failed. Death counts cannot exceed case counts. (validate.py:157)
[2023-08-03 15:00:54] DEBUG : Data test unique_records passed. (validate.py:153)
[2023-08-03 15:00:54] WARNING : Data test no_nulls_test failed. All values are expected to be non-null. (validate.py:157)
[2023-08-03 15:00:54] DEBUG : Data test cases_range_test passed. (validate.py:153)
[2023-08-03 15:00:54] WARNING : Data test deaths_range_test failed. Deaths must be non-negative and <= 100K. (validate.py:157)
[2023-08-03 15:00:54] CRITICAL : 2/5 tests passed. (validate.py:167)
[2023-08-03 15:00:54] INFO : validate info saved successfully to ../data/validation/covid_validation_20230803.csv. (validate.py:130)
[2023-08-03 15:00:54] INFO : => STARTING LOAD... (test_run_elt.py:77)
[2023-08-03 15:00:54] INFO : Saving local source data to local... (test_run_elt.py:78)
[2023-08-03 15:00:54] INFO : Connected to MySQL database... (database_utils.py:88)
[2023-08-03 15:00:54] INFO : covid_db database already exists. (database_utils.py:189)
[2023-08-03 15:00:54] INFO : covid table is created in covid_db (database_utils.py:212)
[2023-08-03 15:00:54] INFO : Data has been loaded to covid_db.covid (database_utils.py:242)
[2023-08-03 15:00:54] INFO : Data saved successfully to ../data/cleaned/covid_cleaned_20230803.csv. (save_data_to_local_utils.py:51)
[2023-08-03 15:00:54] INFO : local source data saved to local. (test_run_elt.py:81)
[2023-08-03 15:00:54] INFO : => STARTING CREATE DATA LOGS... (test_run_elt.py:90)
[2023-08-03 15:00:54] INFO : Starting create data logs (test_run_elt.py:91)
[2023-08-03 15:00:54] INFO : Data saved successfully to covid_monitor_logs.csv . (monitor_logs.py:108)
[2023-08-03 15:00:54] INFO : Connected to MySQL database... (database_utils.py:88)
[2023-08-03 15:00:54] INFO : covid_db database already exists. (database_utils.py:189)
[2023-08-03 15:00:54] INFO : covid_logs table is created in covid_db (database_utils.py:212)
[2023-08-03 15:00:54] INFO : Data has been loaded to covid_db.covid_logs (database_utils.py:242)
[2023-08-03 15:00:54] INFO : Done creating data logs (test_run_elt.py:94)
[2023-08-03 15:00:54] INFO : => SEND DATA VALIDATION EMAIL... (test_run_elt.py:97)
[2023-08-03 15:00:54] INFO : ../data/validation/covid_validation_20230803.csv copied to the ../data/data_for_email successfully. (email_utils.py:67)
[2023-08-03 15:00:54] INFO : ../data/logs/covid_logs_20230803.log copied to the ../data/data_for_email successfully. (email_utils.py:67)
[2023-08-03 15:00:54] INFO : Log file '../data/data_for_email/covid_logs_20230803.log' converted to text file '../data/data_for_email/covid_logs_20230803.txt' successfully. (email_utils.py:97)
[2023-08-03 15:00:54] INFO : Log files processed successfully. (email_utils.py:123)
[2023-08-03 15:00:54] INFO : Log files deleted successfully. (email_utils.py:146)
[2023-08-03 15:00:55] INFO : Successfully connected to the server (email_utils.py:258)
[2023-08-03 15:00:55] INFO : The email has been sent (email_utils.py:323)
[2023-08-03 15:00:55] INFO : Files in the directory deleted successfully. (email_utils.py:38)
[2023-08-03 15:40:21] INFO : Data read successfully from the local CSV file. (extract.py:50)
[2023-08-03 15:40:21] INFO : Done reading CSV data from local (test_run_elt.py:38)
[2023-08-03 15:40:21] INFO : Starting transform with localsource data... (test_run_elt.py:56)
[2023-08-03 15:40:21] INFO : Done transforming localsource data. (test_run_elt.py:58)
[2023-08-03 15:40:21] INFO : => STARTING VALIDATE... (test_run_elt.py:68)
[2023-08-03 15:40:21] INFO : Starting data validation with localsource data... (test_run_elt.py:70)
[2023-08-03 15:40:21] WARNING : Data test cases_vs_deaths failed. Death counts cannot exceed case counts. (validate.py:157)
[2023-08-03 15:40:21] DEBUG : Data test unique_records passed. (validate.py:153)
[2023-08-03 15:40:21] WARNING : Data test no_nulls_test failed. All values are expected to be non-null. (validate.py:157)
[2023-08-03 15:40:21] DEBUG : Data test cases_range_test passed. (validate.py:153)
[2023-08-03 15:40:21] WARNING : Data test deaths_range_test failed. Deaths must be non-negative and <= 100K. (validate.py:157)
[2023-08-03 15:40:21] CRITICAL : 2/5 tests passed. (validate.py:167)
[2023-08-03 15:40:21] INFO : validate info saved successfully to ../data/validation/covid_validation_20230803.csv. (validate.py:130)
[2023-08-03 15:40:21] INFO : => STARTING LOAD... (test_run_elt.py:77)
[2023-08-03 15:40:21] INFO : Saving local source data to local... (test_run_elt.py:78)
[2023-08-03 15:40:21] INFO : Connected to MySQL database... (database_utils.py:88)
[2023-08-03 15:40:21] INFO : covid_db database already exists. (database_utils.py:189)
[2023-08-03 15:40:21] INFO : covid table is created in covid_db (database_utils.py:212)
[2023-08-03 15:40:21] INFO : Data has been loaded to covid_db.covid (database_utils.py:242)
[2023-08-03 15:40:21] INFO : Data saved successfully to ../data/cleaned/covid_cleaned_20230803.csv. (save_data_to_local_utils.py:51)
[2023-08-03 15:40:21] INFO : local source data saved to local. (test_run_elt.py:81)
[2023-08-03 15:40:21] INFO : => STARTING CREATE DATA LOGS... (test_run_elt.py:90)
[2023-08-03 15:40:21] INFO : Starting create data logs (test_run_elt.py:91)
[2023-08-03 15:40:21] INFO : Data saved successfully to covid_monitor_logs.csv . (monitor_logs.py:108)
[2023-08-03 15:40:21] INFO : Connected to MySQL database... (database_utils.py:88)
[2023-08-03 15:40:21] INFO : covid_db database already exists. (database_utils.py:189)
[2023-08-03 15:40:21] INFO : covid_logs table is created in covid_db (database_utils.py:212)
[2023-08-03 15:40:21] INFO : Data has been loaded to covid_db.covid_logs (database_utils.py:242)
[2023-08-03 15:40:21] INFO : Done creating data logs (test_run_elt.py:94)
[2023-08-03 15:40:21] INFO : => SEND DATA VALIDATION EMAIL... (test_run_elt.py:97)
[2023-08-03 15:40:21] INFO : ../data/validation/covid_validation_20230803.csv copied to the ../data/data_for_email successfully. (email_utils.py:67)
[2023-08-03 15:40:21] INFO : ../data/logs/covid_logs_20230803.log copied to the ../data/data_for_email successfully. (email_utils.py:67)
[2023-08-03 15:40:21] INFO : Log file '../data/data_for_email/covid_logs_20230803.log' converted to text file '../data/data_for_email/covid_logs_20230803.txt' successfully. (email_utils.py:97)
[2023-08-03 15:40:21] INFO : Log files processed successfully. (email_utils.py:123)
[2023-08-03 15:40:21] INFO : Log files deleted successfully. (email_utils.py:146)
[2023-08-03 15:40:22] INFO : Successfully connected to the server (email_utils.py:258)
[2023-08-03 15:40:22] INFO : The email has been sent (email_utils.py:323)
[2023-08-03 15:40:22] INFO : Files in the directory deleted successfully. (email_utils.py:38)
