[2023-08-02 20:50:34] INFO : Data read successfully from the local CSV file. (extract.py:50)
[2023-08-02 20:50:34] INFO : Done reading CSV data from local (test_run_elt.py:38)
[2023-08-02 20:50:34] INFO : Starting transform with localsource data... (test_run_elt.py:56)
[2023-08-02 20:50:34] INFO : Done transforming localsource data. (test_run_elt.py:58)
[2023-08-02 20:50:34] INFO : => STARTING VALIDATE... (test_run_elt.py:68)
[2023-08-02 20:50:34] INFO : Starting data validation with localsource data... (test_run_elt.py:70)
[2023-08-02 20:50:34] WARNING : Data test cases_vs_deaths failed. Death counts cannot exceed case counts. (validate.py:157)
[2023-08-02 20:50:34] DEBUG : Data test unique_records passed. (validate.py:153)
[2023-08-02 20:50:34] WARNING : Data test no_nulls_test failed. All values are expected to be non-null. (validate.py:157)
[2023-08-02 20:50:34] DEBUG : Data test cases_range_test passed. (validate.py:153)
[2023-08-02 20:50:34] WARNING : Data test deaths_range_test failed. Deaths must be non-negative and <= 100K. (validate.py:157)
[2023-08-02 20:50:34] CRITICAL : 2/5 tests passed. (validate.py:167)
[2023-08-02 20:50:34] INFO : validate info saved successfully to ../data/validation/covid_validation_20230802.csv. (validate.py:130)
[2023-08-02 20:50:34] INFO : => STARTING LOAD... (test_run_elt.py:77)
[2023-08-02 20:50:34] INFO : Saving local source data to local... (test_run_elt.py:78)
[2023-08-02 20:50:34] INFO : Connected to MySQL database... (database_utils.py:88)
[2023-08-02 20:50:34] INFO : covid_db database already exists. (database_utils.py:190)
[2023-08-02 20:50:34] INFO : covid table is created in covid_db (database_utils.py:213)
[2023-08-02 20:50:34] INFO : Data has been loaded to covid_db.covid (database_utils.py:243)
[2023-08-02 20:50:35] INFO : local source data saved to local. (test_run_elt.py:81)
[2023-08-02 20:50:35] INFO : => STARTING CREATE DATA LOGS... (test_run_elt.py:90)
[2023-08-02 20:50:35] INFO : Starting create data logs (test_run_elt.py:91)
[2023-08-02 20:50:35] INFO : Data saved successfully to covid_monitor_logs.csv . (monitor_logs.py:108)
[2023-08-02 20:50:35] INFO : Connected to MySQL database... (database_utils.py:88)
[2023-08-02 20:50:35] INFO : covid_db database already exists. (database_utils.py:190)
[2023-08-02 20:50:35] INFO : covid_logs table is created in covid_db (database_utils.py:213)
[2023-08-02 20:50:35] INFO : Data has been loaded to covid_db.covid_logs (database_utils.py:243)
[2023-08-02 20:50:35] INFO : Done creating data logs (test_run_elt.py:94)
[2023-08-02 20:50:35] INFO : => SEND DATA VALIDATION EMAIL... (test_run_elt.py:97)
[2023-08-02 20:50:35] INFO : ../data/validation/covid_validation_20230802.csv copied to the ../data/data_for_email successfully. (email_utils.py:67)
[2023-08-02 20:50:35] INFO : ../data/logs/covid_logs_20230801.log copied to the ../data/data_for_email successfully. (email_utils.py:67)
[2023-08-02 20:50:35] INFO : Log file '../data/data_for_email/covid_logs_20230801.log' converted to text file '../data/data_for_email/covid_logs_20230801.txt' successfully. (email_utils.py:97)
[2023-08-02 20:50:35] INFO : Log files processed successfully. (email_utils.py:123)
[2023-08-02 20:50:35] INFO : Log files deleted successfully. (email_utils.py:146)
[2023-08-02 20:50:35] INFO : Successfully connected to the server (email_utils.py:259)
[2023-08-02 20:50:36] INFO : The email has been sent (email_utils.py:325)
[2023-08-02 20:50:36] INFO : Files in the directory deleted successfully. (email_utils.py:38)
